{"trial_id": "1", "hyperparameters": {"space": [{"class_name": "Int", "config": {"name": "units", "default": null, "conditions": [], "min_value": 32, "max_value": 512, "step": 32, "sampling": "linear"}}, {"class_name": "Float", "config": {"name": "dropout", "default": 0.1, "conditions": [], "min_value": 0.1, "max_value": 0.5, "step": 0.1, "sampling": "linear"}}, {"class_name": "Float", "config": {"name": "learning_rate", "default": 0.0001, "conditions": [], "min_value": 0.0001, "max_value": 0.01, "step": null, "sampling": "log"}}], "values": {"units": 416, "dropout": 0.1, "learning_rate": 0.0010428149205237449}}, "metrics": {"metrics": {}}, "score": null, "best_step": 0, "status": "FAILED", "message": "Traceback (most recent call last):\n  File \"C:\\Users\\lsaka\\AppData\\Local\\Programs\\Python\\Python310\\lib\\site-packages\\keras_tuner\\src\\engine\\base_tuner.py\", line 274, in _try_run_and_update_trial\n    self._run_and_update_trial(trial, *fit_args, **fit_kwargs)\n  File \"C:\\Users\\lsaka\\AppData\\Local\\Programs\\Python\\Python310\\lib\\site-packages\\keras_tuner\\src\\engine\\base_tuner.py\", line 239, in _run_and_update_trial\n    results = self.run_trial(trial, *fit_args, **fit_kwargs)\n  File \"C:\\Users\\lsaka\\AppData\\Local\\Programs\\Python\\Python310\\lib\\site-packages\\keras_tuner\\src\\engine\\tuner.py\", line 314, in run_trial\n    obj_value = self._build_and_fit_model(trial, *args, **copied_kwargs)\n  File \"C:\\Users\\lsaka\\AppData\\Local\\Programs\\Python\\Python310\\lib\\site-packages\\keras_tuner\\src\\engine\\tuner.py\", line 233, in _build_and_fit_model\n    results = self.hypermodel.fit(hp, model, *args, **kwargs)\n  File \"C:\\Users\\lsaka\\AppData\\Local\\Programs\\Python\\Python310\\lib\\site-packages\\keras_tuner\\src\\engine\\hypermodel.py\", line 149, in fit\n    return model.fit(*args, **kwargs)\n  File \"C:\\Users\\lsaka\\AppData\\Local\\Programs\\Python\\Python310\\lib\\site-packages\\keras\\src\\utils\\traceback_utils.py\", line 122, in error_handler\n    raise e.with_traceback(filtered_tb) from None\n  File \"C:\\Users\\lsaka\\AppData\\Local\\Programs\\Python\\Python310\\lib\\site-packages\\keras\\src\\models\\functional.py\", line 264, in _adjust_input_rank\n    raise ValueError(\nValueError: Exception encountered when calling Sequential.call().\n\n\u001b[1mInvalid input shape for input Tensor(\"data:0\", shape=(None, 37), dtype=float32). Expected shape (None, 10, 33), but input has incompatible shape (None, 37)\u001b[0m\n\nArguments received by Sequential.call():\n  \u2022 inputs=tf.Tensor(shape=(None, 37), dtype=float32)\n  \u2022 training=True\n  \u2022 mask=None\n"}