{"trial_id": "00", "hyperparameters": {"space": [{"class_name": "Int", "config": {"name": "units", "default": null, "conditions": [], "min_value": 50, "max_value": 200, "step": 50, "sampling": "linear"}}, {"class_name": "Boolean", "config": {"name": "add_layer", "default": false, "conditions": []}}, {"class_name": "Float", "config": {"name": "dropout_rate", "default": 0.2, "conditions": [], "min_value": 0.2, "max_value": 0.5, "step": 0.1, "sampling": "linear"}}], "values": {"units": 50, "add_layer": false, "dropout_rate": 0.30000000000000004}}, "metrics": {"metrics": {}}, "score": null, "best_step": 0, "status": "FAILED", "message": "Traceback (most recent call last):\n  File \"C:\\Users\\lsaka\\AppData\\Local\\Programs\\Python\\Python310\\lib\\site-packages\\keras_tuner\\src\\engine\\base_tuner.py\", line 274, in _try_run_and_update_trial\n    self._run_and_update_trial(trial, *fit_args, **fit_kwargs)\n  File \"C:\\Users\\lsaka\\AppData\\Local\\Programs\\Python\\Python310\\lib\\site-packages\\keras_tuner\\src\\engine\\base_tuner.py\", line 239, in _run_and_update_trial\n    results = self.run_trial(trial, *fit_args, **fit_kwargs)\n  File \"C:\\Users\\lsaka\\AppData\\Local\\Programs\\Python\\Python310\\lib\\site-packages\\keras_tuner\\src\\engine\\tuner.py\", line 314, in run_trial\n    obj_value = self._build_and_fit_model(trial, *args, **copied_kwargs)\n  File \"C:\\Users\\lsaka\\AppData\\Local\\Programs\\Python\\Python310\\lib\\site-packages\\keras_tuner\\src\\engine\\tuner.py\", line 233, in _build_and_fit_model\n    results = self.hypermodel.fit(hp, model, *args, **kwargs)\n  File \"C:\\Users\\lsaka\\AppData\\Local\\Programs\\Python\\Python310\\lib\\site-packages\\keras_tuner\\src\\engine\\hypermodel.py\", line 149, in fit\n    return model.fit(*args, **kwargs)\n  File \"C:\\Users\\lsaka\\AppData\\Local\\Programs\\Python\\Python310\\lib\\site-packages\\keras\\src\\utils\\traceback_utils.py\", line 122, in error_handler\n    raise e.with_traceback(filtered_tb) from None\n  File \"C:\\Users\\lsaka\\AppData\\Local\\Programs\\Python\\Python310\\lib\\site-packages\\tensorflow\\python\\eager\\execute.py\", line 53, in quick_execute\n    tensors = pywrap_tfe.TFE_Py_Execute(ctx._handle, device_name, op_name,\ntensorflow.python.framework.errors_impl.InvalidArgumentError: Graph execution error:\n\nDetected at node gradient_tape/compile_loss/mean_squared_error/sub/BroadcastGradientArgs defined at (most recent call last):\n  File \"C:\\Users\\lsaka\\Desktop\\Numbers\\loto7\\scrapingloto7_4.py\", line 103, in <module>\n\n  File \"C:\\Users\\lsaka\\AppData\\Local\\Programs\\Python\\Python310\\lib\\site-packages\\keras_tuner\\src\\engine\\base_tuner.py\", line 234, in search\n\n  File \"C:\\Users\\lsaka\\AppData\\Local\\Programs\\Python\\Python310\\lib\\site-packages\\keras_tuner\\src\\engine\\base_tuner.py\", line 274, in _try_run_and_update_trial\n\n  File \"C:\\Users\\lsaka\\AppData\\Local\\Programs\\Python\\Python310\\lib\\site-packages\\keras_tuner\\src\\engine\\base_tuner.py\", line 239, in _run_and_update_trial\n\n  File \"C:\\Users\\lsaka\\AppData\\Local\\Programs\\Python\\Python310\\lib\\site-packages\\keras_tuner\\src\\engine\\tuner.py\", line 314, in run_trial\n\n  File \"C:\\Users\\lsaka\\AppData\\Local\\Programs\\Python\\Python310\\lib\\site-packages\\keras_tuner\\src\\engine\\tuner.py\", line 233, in _build_and_fit_model\n\n  File \"C:\\Users\\lsaka\\AppData\\Local\\Programs\\Python\\Python310\\lib\\site-packages\\keras_tuner\\src\\engine\\hypermodel.py\", line 149, in fit\n\n  File \"C:\\Users\\lsaka\\AppData\\Local\\Programs\\Python\\Python310\\lib\\site-packages\\keras\\src\\utils\\traceback_utils.py\", line 117, in error_handler\n\n  File \"C:\\Users\\lsaka\\AppData\\Local\\Programs\\Python\\Python310\\lib\\site-packages\\keras\\src\\backend\\tensorflow\\trainer.py\", line 320, in fit\n\n  File \"C:\\Users\\lsaka\\AppData\\Local\\Programs\\Python\\Python310\\lib\\site-packages\\keras\\src\\backend\\tensorflow\\trainer.py\", line 121, in one_step_on_iterator\n\n  File \"C:\\Users\\lsaka\\AppData\\Local\\Programs\\Python\\Python310\\lib\\site-packages\\keras\\src\\backend\\tensorflow\\trainer.py\", line 108, in one_step_on_data\n\n  File \"C:\\Users\\lsaka\\AppData\\Local\\Programs\\Python\\Python310\\lib\\site-packages\\keras\\src\\backend\\tensorflow\\trainer.py\", line 70, in train_step\n\nIncompatible shapes: [32,7] vs. [32,10,7]\n\t [[{{node gradient_tape/compile_loss/mean_squared_error/sub/BroadcastGradientArgs}}]] [Op:__inference_one_step_on_iterator_2289]\n"}